[2025-09-11T10:55:49.994+0000] {local_task_job_runner.py:120} INFO - ::group::Pre task execution logs
[2025-09-11T10:55:50.128+0000] {taskinstance.py:2076} INFO - Dependencies all met for dep_context=non-requeueable deps ti=<TaskInstance: 1_logistics_airbyte_ingestion_dbt_silver.dbt_test manual__2025-09-11T10:55:25.483094+00:00 [queued]>
[2025-09-11T10:55:50.171+0000] {taskinstance.py:2076} INFO - Dependencies all met for dep_context=requeueable deps ti=<TaskInstance: 1_logistics_airbyte_ingestion_dbt_silver.dbt_test manual__2025-09-11T10:55:25.483094+00:00 [queued]>
[2025-09-11T10:55:50.172+0000] {taskinstance.py:2306} INFO - Starting attempt 1 of 1
[2025-09-11T10:55:50.286+0000] {taskinstance.py:2330} INFO - Executing <Task(BashOperator): dbt_test> on 2025-09-11 10:55:25.483094+00:00
[2025-09-11T10:55:50.321+0000] {standard_task_runner.py:63} INFO - Started process 3373 to run task
[2025-09-11T10:55:50.340+0000] {standard_task_runner.py:90} INFO - Running: ['airflow', 'tasks', 'run', '1_logistics_airbyte_ingestion_dbt_silver', 'dbt_test', 'manual__2025-09-11T10:55:25.483094+00:00', '--job-id', '1058', '--raw', '--subdir', 'DAGS_FOLDER/1_logistics-airbyte-dbt.py', '--cfg-path', '/tmp/tmpxlb20sfr']
[2025-09-11T10:55:50.347+0000] {standard_task_runner.py:91} INFO - Job 1058: Subtask dbt_test
[2025-09-11T10:55:50.652+0000] {task_command.py:426} INFO - Running <TaskInstance: 1_logistics_airbyte_ingestion_dbt_silver.dbt_test manual__2025-09-11T10:55:25.483094+00:00 [running]> on host e9e7ede241a8
[2025-09-11T10:55:51.005+0000] {taskinstance.py:2648} INFO - Exporting env vars: AIRFLOW_CTX_DAG_EMAIL='benjaminimp10@gmail.com' AIRFLOW_CTX_DAG_OWNER='airflow' AIRFLOW_CTX_DAG_ID='1_logistics_airbyte_ingestion_dbt_silver' AIRFLOW_CTX_TASK_ID='dbt_test' AIRFLOW_CTX_EXECUTION_DATE='2025-09-11T10:55:25.483094+00:00' AIRFLOW_CTX_TRY_NUMBER='1' AIRFLOW_CTX_DAG_RUN_ID='manual__2025-09-11T10:55:25.483094+00:00'
[2025-09-11T10:55:51.007+0000] {taskinstance.py:430} INFO - ::endgroup::
[2025-09-11T10:55:51.065+0000] {subprocess.py:63} INFO - Tmp dir root location: /tmp
[2025-09-11T10:55:51.069+0000] {subprocess.py:75} INFO - Running command: ['/usr/bin/bash', '-c', 'cd /opt/airflow/dbt/dbt-project && dbt test']
[2025-09-11T10:55:51.097+0000] {subprocess.py:86} INFO - Output:
[2025-09-11T10:56:01.178+0000] {subprocess.py:93} INFO - [0m10:56:01  Running with dbt=1.8.8
[2025-09-11T10:56:04.579+0000] {subprocess.py:93} INFO - [0m10:56:04  Registered adapter: snowflake=1.8.4
[2025-09-11T10:56:05.876+0000] {subprocess.py:93} INFO - [0m10:56:05  Unable to do partial parsing because of a version mismatch
[2025-09-11T10:56:19.579+0000] {subprocess.py:93} INFO - [0m10:56:19  [[33mWARNING[0m]: Deprecated functionality
[2025-09-11T10:56:19.581+0000] {subprocess.py:93} INFO - The `tests` config has been renamed to `data_tests`. Please see
[2025-09-11T10:56:19.582+0000] {subprocess.py:93} INFO - https://docs.getdbt.com/docs/build/data-tests#new-data_tests-syntax for more
[2025-09-11T10:56:19.584+0000] {subprocess.py:93} INFO - information.
[2025-09-11T10:56:20.982+0000] {subprocess.py:93} INFO - [0m10:56:20  [[33mWARNING[0m]: Test 'test.logistics_project.source_relationships_LOGISTICS_RAW_inventory_PRODUCT_ID__PRODUCT_ID__ref_product_.f4aee8c92f' (models/schema.yml) depends on a node named 'product' in package '' which was not found
[2025-09-11T10:56:20.988+0000] {subprocess.py:93} INFO - [0m10:56:20  [[33mWARNING[0m]: Test 'test.logistics_project.source_relationships_LOGISTICS_RAW_inventory_SELLER_ID__SELLER_ID__ref_seller_.1c2f5db1e9' (models/schema.yml) depends on a node named 'seller' in package '' which was not found
[2025-09-11T10:56:20.993+0000] {subprocess.py:93} INFO - [0m10:56:20  [[33mWARNING[0m]: Test 'test.logistics_project.source_relationships_LOGISTICS_RAW_orders_CUSTOMER_ID__CUSTOMER_ID__ref_customers_.924af4fc27' (models/schema.yml) depends on a node named 'customers' in package '' which was not found
[2025-09-11T10:56:21.001+0000] {subprocess.py:93} INFO - [0m10:56:21  [[33mWARNING[0m]: Test 'test.logistics_project.source_relationships_LOGISTICS_RAW_orders_PRODUCT_ID__PRODUCT_ID__ref_products_.c4706cdb93' (models/schema.yml) depends on a node named 'products' in package '' which was not found
[2025-09-11T10:56:21.705+0000] {subprocess.py:93} INFO - [0m10:56:21  [[33mWARNING[0m]: Configuration paths exist in your dbt_project.yml file which do not apply to any resources.
[2025-09-11T10:56:21.707+0000] {subprocess.py:93} INFO - There are 1 unused configuration paths:
[2025-09-11T10:56:21.708+0000] {subprocess.py:93} INFO - - snapshots.customers
[2025-09-11T10:56:22.539+0000] {subprocess.py:93} INFO - [0m10:56:22  Found 18 models, 1 snapshot, 1 seed, 24 data tests, 8 sources, 726 macros
[2025-09-11T10:56:22.586+0000] {subprocess.py:93} INFO - [0m10:56:22
[2025-09-11T10:56:29.784+0000] {subprocess.py:93} INFO - [0m10:56:29
[2025-09-11T10:56:29.800+0000] {subprocess.py:93} INFO - [0m10:56:29  Finished running  in 0 hours 0 minutes and 7.18 seconds (7.18s).
[2025-09-11T10:56:29.821+0000] {subprocess.py:93} INFO - [0m10:56:29  Encountered an error:
[2025-09-11T10:56:29.827+0000] {subprocess.py:93} INFO - Database Error
[2025-09-11T10:56:29.831+0000] {subprocess.py:93} INFO -   250001 (08001): Failed to connect to DB: IVSIOOT-IOC95490.snowflakecomputing.com:443. Incorrect username or password was specified.
[2025-09-11T10:56:34.228+0000] {subprocess.py:97} INFO - Command exited with return code 2
[2025-09-11T10:56:34.233+0000] {taskinstance.py:441} INFO - ::group::Post task execution logs
[2025-09-11T10:56:34.285+0000] {taskinstance.py:2905} ERROR - Task failed with exception
Traceback (most recent call last):
  File "/home/airflow/.local/lib/python3.11/site-packages/airflow/models/taskinstance.py", line 465, in _execute_task
    result = _execute_callable(context=context, **execute_callable_kwargs)
             ^^^^^^^^^^^^^^^^^^^^^^^^^^^^^^^^^^^^^^^^^^^^^^^^^^^^^^^^^^^^^
  File "/home/airflow/.local/lib/python3.11/site-packages/airflow/models/taskinstance.py", line 432, in _execute_callable
    return execute_callable(context=context, **execute_callable_kwargs)
           ^^^^^^^^^^^^^^^^^^^^^^^^^^^^^^^^^^^^^^^^^^^^^^^^^^^^^^^^^^^^
  File "/home/airflow/.local/lib/python3.11/site-packages/airflow/models/baseoperator.py", line 400, in wrapper
    return func(self, *args, **kwargs)
           ^^^^^^^^^^^^^^^^^^^^^^^^^^^
  File "/home/airflow/.local/lib/python3.11/site-packages/airflow/operators/bash.py", line 243, in execute
    raise AirflowException(
airflow.exceptions.AirflowException: Bash command failed. The command returned a non-zero exit code 2.
[2025-09-11T10:56:34.305+0000] {taskinstance.py:1206} INFO - Marking task as FAILED. dag_id=1_logistics_airbyte_ingestion_dbt_silver, task_id=dbt_test, run_id=manual__2025-09-11T10:55:25.483094+00:00, execution_date=20250911T105525, start_date=20250911T105550, end_date=20250911T105634
[2025-09-11T10:56:34.372+0000] {logging_mixin.py:188} WARNING - /home/airflow/.local/lib/python3.11/site-packages/airflow/utils/email.py:154 RemovedInAirflow3Warning: Fetching SMTP credentials from configuration variables will be deprecated in a future release. Please set credentials using a connection instead.
[2025-09-11T10:56:34.373+0000] {configuration.py:1050} WARNING - section/key [smtp/smtp_user] not found in config
[2025-09-11T10:56:34.374+0000] {email.py:271} INFO - Email alerting: attempt 1
[2025-09-11T10:56:34.407+0000] {configuration.py:1050} WARNING - section/key [smtp/smtp_user] not found in config
[2025-09-11T10:56:34.408+0000] {email.py:271} INFO - Email alerting: attempt 1
[2025-09-11T10:56:34.410+0000] {taskinstance.py:879} ERROR - Failed to send email to: ['benjaminimp10@gmail.com']
Traceback (most recent call last):
  File "/home/airflow/.local/lib/python3.11/site-packages/airflow/models/taskinstance.py", line 2479, in _run_raw_task
    self._execute_task_with_callbacks(context, test_mode, session=session)
  File "/home/airflow/.local/lib/python3.11/site-packages/airflow/models/taskinstance.py", line 2676, in _execute_task_with_callbacks
    result = self._execute_task(context, task_orig)
             ^^^^^^^^^^^^^^^^^^^^^^^^^^^^^^^^^^^^^^
  File "/home/airflow/.local/lib/python3.11/site-packages/airflow/models/taskinstance.py", line 2701, in _execute_task
    return _execute_task(self, context, task_orig)
           ^^^^^^^^^^^^^^^^^^^^^^^^^^^^^^^^^^^^^^^
  File "/home/airflow/.local/lib/python3.11/site-packages/airflow/models/taskinstance.py", line 465, in _execute_task
    result = _execute_callable(context=context, **execute_callable_kwargs)
             ^^^^^^^^^^^^^^^^^^^^^^^^^^^^^^^^^^^^^^^^^^^^^^^^^^^^^^^^^^^^^
  File "/home/airflow/.local/lib/python3.11/site-packages/airflow/models/taskinstance.py", line 432, in _execute_callable
    return execute_callable(context=context, **execute_callable_kwargs)
           ^^^^^^^^^^^^^^^^^^^^^^^^^^^^^^^^^^^^^^^^^^^^^^^^^^^^^^^^^^^^
  File "/home/airflow/.local/lib/python3.11/site-packages/airflow/models/baseoperator.py", line 400, in wrapper
    return func(self, *args, **kwargs)
           ^^^^^^^^^^^^^^^^^^^^^^^^^^^
  File "/home/airflow/.local/lib/python3.11/site-packages/airflow/operators/bash.py", line 243, in execute
    raise AirflowException(
airflow.exceptions.AirflowException: Bash command failed. The command returned a non-zero exit code 2.

During handling of the above exception, another exception occurred:

Traceback (most recent call last):
  File "/home/airflow/.local/lib/python3.11/site-packages/airflow/models/taskinstance.py", line 1063, in _email_alert
    send_email(task.email, subject, html_content)
  File "/home/airflow/.local/lib/python3.11/site-packages/airflow/utils/email.py", line 80, in send_email
    return backend(
           ^^^^^^^^
  File "/home/airflow/.local/lib/python3.11/site-packages/airflow/utils/email.py", line 154, in send_email_smtp
    send_mime_email(e_from=mail_from, e_to=recipients, mime_msg=msg, conn_id=conn_id, dryrun=dryrun)
  File "/home/airflow/.local/lib/python3.11/site-packages/airflow/utils/email.py", line 273, in send_mime_email
    smtp_conn = _get_smtp_connection(smtp_host, smtp_port, smtp_timeout, smtp_ssl)
                ^^^^^^^^^^^^^^^^^^^^^^^^^^^^^^^^^^^^^^^^^^^^^^^^^^^^^^^^^^^^^^^^^^
  File "/home/airflow/.local/lib/python3.11/site-packages/airflow/utils/email.py", line 317, in _get_smtp_connection
    return smtplib.SMTP(host=host, port=port, timeout=timeout)
           ^^^^^^^^^^^^^^^^^^^^^^^^^^^^^^^^^^^^^^^^^^^^^^^^^^^
  File "/usr/local/lib/python3.11/smtplib.py", line 255, in __init__
    (code, msg) = self.connect(host, port)
                  ^^^^^^^^^^^^^^^^^^^^^^^^
  File "/usr/local/lib/python3.11/smtplib.py", line 341, in connect
    self.sock = self._get_socket(host, port, self.timeout)
                ^^^^^^^^^^^^^^^^^^^^^^^^^^^^^^^^^^^^^^^^^^
  File "/usr/local/lib/python3.11/smtplib.py", line 312, in _get_socket
    return socket.create_connection((host, port), timeout,
           ^^^^^^^^^^^^^^^^^^^^^^^^^^^^^^^^^^^^^^^^^^^^^^^
  File "/usr/local/lib/python3.11/socket.py", line 851, in create_connection
    raise exceptions[0]
  File "/usr/local/lib/python3.11/socket.py", line 836, in create_connection
    sock.connect(sa)
ConnectionRefusedError: [Errno 111] Connection refused

During handling of the above exception, another exception occurred:

Traceback (most recent call last):
  File "/home/airflow/.local/lib/python3.11/site-packages/airflow/models/taskinstance.py", line 877, in _handle_failure
    task_instance.email_alert(error, failure_context["task"])
  File "/home/airflow/.local/lib/python3.11/site-packages/airflow/models/taskinstance.py", line 3163, in email_alert
    _email_alert(task_instance=self, exception=exception, task=task)
  File "/home/airflow/.local/lib/python3.11/site-packages/airflow/models/taskinstance.py", line 1065, in _email_alert
    send_email(task.email, subject, html_content_err)
  File "/home/airflow/.local/lib/python3.11/site-packages/airflow/utils/email.py", line 80, in send_email
    return backend(
           ^^^^^^^^
  File "/home/airflow/.local/lib/python3.11/site-packages/airflow/utils/email.py", line 154, in send_email_smtp
    send_mime_email(e_from=mail_from, e_to=recipients, mime_msg=msg, conn_id=conn_id, dryrun=dryrun)
  File "/home/airflow/.local/lib/python3.11/site-packages/airflow/utils/email.py", line 273, in send_mime_email
    smtp_conn = _get_smtp_connection(smtp_host, smtp_port, smtp_timeout, smtp_ssl)
                ^^^^^^^^^^^^^^^^^^^^^^^^^^^^^^^^^^^^^^^^^^^^^^^^^^^^^^^^^^^^^^^^^^
  File "/home/airflow/.local/lib/python3.11/site-packages/airflow/utils/email.py", line 317, in _get_smtp_connection
    return smtplib.SMTP(host=host, port=port, timeout=timeout)
           ^^^^^^^^^^^^^^^^^^^^^^^^^^^^^^^^^^^^^^^^^^^^^^^^^^^
  File "/usr/local/lib/python3.11/smtplib.py", line 255, in __init__
    (code, msg) = self.connect(host, port)
                  ^^^^^^^^^^^^^^^^^^^^^^^^
  File "/usr/local/lib/python3.11/smtplib.py", line 341, in connect
    self.sock = self._get_socket(host, port, self.timeout)
                ^^^^^^^^^^^^^^^^^^^^^^^^^^^^^^^^^^^^^^^^^^
  File "/usr/local/lib/python3.11/smtplib.py", line 312, in _get_socket
    return socket.create_connection((host, port), timeout,
           ^^^^^^^^^^^^^^^^^^^^^^^^^^^^^^^^^^^^^^^^^^^^^^^
  File "/usr/local/lib/python3.11/socket.py", line 851, in create_connection
    raise exceptions[0]
  File "/usr/local/lib/python3.11/socket.py", line 836, in create_connection
    sock.connect(sa)
ConnectionRefusedError: [Errno 111] Connection refused
[2025-09-11T10:56:34.502+0000] {standard_task_runner.py:110} ERROR - Failed to execute job 1058 for task dbt_test (Bash command failed. The command returned a non-zero exit code 2.; 3373)
[2025-09-11T10:56:34.542+0000] {local_task_job_runner.py:240} INFO - Task exited with return code 1
[2025-09-11T10:56:34.672+0000] {taskinstance.py:3498} INFO - 0 downstream tasks scheduled from follow-on schedule check
[2025-09-11T10:56:34.790+0000] {local_task_job_runner.py:222} INFO - ::endgroup::
