[2025-09-11T10:22:43.654+0000] {local_task_job_runner.py:120} INFO - ::group::Pre task execution logs
[2025-09-11T10:22:43.883+0000] {taskinstance.py:2076} INFO - Dependencies all met for dep_context=non-requeueable deps ti=<TaskInstance: 1_logistics_airbyte_ingestion_dbt_silver.dbt_test manual__2025-09-11T10:22:01.903735+00:00 [queued]>
[2025-09-11T10:22:43.934+0000] {taskinstance.py:2076} INFO - Dependencies all met for dep_context=requeueable deps ti=<TaskInstance: 1_logistics_airbyte_ingestion_dbt_silver.dbt_test manual__2025-09-11T10:22:01.903735+00:00 [queued]>
[2025-09-11T10:22:43.935+0000] {taskinstance.py:2306} INFO - Starting attempt 1 of 1
[2025-09-11T10:22:44.075+0000] {taskinstance.py:2330} INFO - Executing <Task(BashOperator): dbt_test> on 2025-09-11 10:22:01.903735+00:00
[2025-09-11T10:22:44.113+0000] {standard_task_runner.py:63} INFO - Started process 2744 to run task
[2025-09-11T10:22:44.141+0000] {standard_task_runner.py:90} INFO - Running: ['airflow', 'tasks', 'run', '1_logistics_airbyte_ingestion_dbt_silver', 'dbt_test', 'manual__2025-09-11T10:22:01.903735+00:00', '--job-id', '1057', '--raw', '--subdir', 'DAGS_FOLDER/1_logistics-airbyte-dbt.py', '--cfg-path', '/tmp/tmps7y873h2']
[2025-09-11T10:22:44.170+0000] {standard_task_runner.py:91} INFO - Job 1057: Subtask dbt_test
[2025-09-11T10:22:44.626+0000] {task_command.py:426} INFO - Running <TaskInstance: 1_logistics_airbyte_ingestion_dbt_silver.dbt_test manual__2025-09-11T10:22:01.903735+00:00 [running]> on host e9e7ede241a8
[2025-09-11T10:22:45.232+0000] {taskinstance.py:2648} INFO - Exporting env vars: AIRFLOW_CTX_DAG_EMAIL='benjaminimp10@gmail.com' AIRFLOW_CTX_DAG_OWNER='airflow' AIRFLOW_CTX_DAG_ID='1_logistics_airbyte_ingestion_dbt_silver' AIRFLOW_CTX_TASK_ID='dbt_test' AIRFLOW_CTX_EXECUTION_DATE='2025-09-11T10:22:01.903735+00:00' AIRFLOW_CTX_TRY_NUMBER='1' AIRFLOW_CTX_DAG_RUN_ID='manual__2025-09-11T10:22:01.903735+00:00'
[2025-09-11T10:22:45.234+0000] {taskinstance.py:430} INFO - ::endgroup::
[2025-09-11T10:22:45.315+0000] {subprocess.py:63} INFO - Tmp dir root location: /tmp
[2025-09-11T10:22:45.318+0000] {subprocess.py:75} INFO - Running command: ['/usr/bin/bash', '-c', 'cd /opt/airflow/dbt/dbt-project && dbt test']
[2025-09-11T10:22:45.339+0000] {subprocess.py:86} INFO - Output:
[2025-09-11T10:22:59.968+0000] {subprocess.py:93} INFO - [0m10:22:59  Running with dbt=1.8.8
[2025-09-11T10:23:10.140+0000] {subprocess.py:93} INFO - [0m10:23:10  Registered adapter: snowflake=1.8.4
[2025-09-11T10:23:18.172+0000] {subprocess.py:93} INFO - [0m10:23:18  [[33mWARNING[0m]: Configuration paths exist in your dbt_project.yml file which do not apply to any resources.
[2025-09-11T10:23:18.173+0000] {subprocess.py:93} INFO - There are 1 unused configuration paths:
[2025-09-11T10:23:18.174+0000] {subprocess.py:93} INFO - - snapshots.customers
[2025-09-11T10:23:18.810+0000] {subprocess.py:93} INFO - [0m10:23:18  Found 18 models, 1 snapshot, 1 seed, 24 data tests, 8 sources, 726 macros
[2025-09-11T10:23:18.831+0000] {subprocess.py:93} INFO - [0m10:23:18
[2025-09-11T10:23:24.714+0000] {subprocess.py:93} INFO - [0m10:23:24
[2025-09-11T10:23:24.716+0000] {subprocess.py:93} INFO - [0m10:23:24  Finished running  in 0 hours 0 minutes and 5.88 seconds (5.88s).
[2025-09-11T10:23:24.719+0000] {subprocess.py:93} INFO - [0m10:23:24  Encountered an error:
[2025-09-11T10:23:24.720+0000] {subprocess.py:93} INFO - Database Error
[2025-09-11T10:23:24.720+0000] {subprocess.py:93} INFO -   250001 (08001): Failed to connect to DB: IVSIOOT-IOC95490.snowflakecomputing.com:443. Incorrect username or password was specified.
[2025-09-11T10:23:29.257+0000] {subprocess.py:97} INFO - Command exited with return code 2
[2025-09-11T10:23:29.263+0000] {taskinstance.py:441} INFO - ::group::Post task execution logs
[2025-09-11T10:23:29.320+0000] {taskinstance.py:2905} ERROR - Task failed with exception
Traceback (most recent call last):
  File "/home/airflow/.local/lib/python3.11/site-packages/airflow/models/taskinstance.py", line 465, in _execute_task
    result = _execute_callable(context=context, **execute_callable_kwargs)
             ^^^^^^^^^^^^^^^^^^^^^^^^^^^^^^^^^^^^^^^^^^^^^^^^^^^^^^^^^^^^^
  File "/home/airflow/.local/lib/python3.11/site-packages/airflow/models/taskinstance.py", line 432, in _execute_callable
    return execute_callable(context=context, **execute_callable_kwargs)
           ^^^^^^^^^^^^^^^^^^^^^^^^^^^^^^^^^^^^^^^^^^^^^^^^^^^^^^^^^^^^
  File "/home/airflow/.local/lib/python3.11/site-packages/airflow/models/baseoperator.py", line 400, in wrapper
    return func(self, *args, **kwargs)
           ^^^^^^^^^^^^^^^^^^^^^^^^^^^
  File "/home/airflow/.local/lib/python3.11/site-packages/airflow/operators/bash.py", line 243, in execute
    raise AirflowException(
airflow.exceptions.AirflowException: Bash command failed. The command returned a non-zero exit code 2.
[2025-09-11T10:23:29.344+0000] {taskinstance.py:1206} INFO - Marking task as FAILED. dag_id=1_logistics_airbyte_ingestion_dbt_silver, task_id=dbt_test, run_id=manual__2025-09-11T10:22:01.903735+00:00, execution_date=20250911T102201, start_date=20250911T102243, end_date=20250911T102329
[2025-09-11T10:23:29.427+0000] {logging_mixin.py:188} WARNING - /home/airflow/.local/lib/python3.11/site-packages/airflow/utils/email.py:154 RemovedInAirflow3Warning: Fetching SMTP credentials from configuration variables will be deprecated in a future release. Please set credentials using a connection instead.
[2025-09-11T10:23:29.428+0000] {configuration.py:1050} WARNING - section/key [smtp/smtp_user] not found in config
[2025-09-11T10:23:29.429+0000] {email.py:271} INFO - Email alerting: attempt 1
[2025-09-11T10:23:29.460+0000] {configuration.py:1050} WARNING - section/key [smtp/smtp_user] not found in config
[2025-09-11T10:23:29.461+0000] {email.py:271} INFO - Email alerting: attempt 1
[2025-09-11T10:23:29.463+0000] {taskinstance.py:879} ERROR - Failed to send email to: ['benjaminimp10@gmail.com']
Traceback (most recent call last):
  File "/home/airflow/.local/lib/python3.11/site-packages/airflow/models/taskinstance.py", line 2479, in _run_raw_task
    self._execute_task_with_callbacks(context, test_mode, session=session)
  File "/home/airflow/.local/lib/python3.11/site-packages/airflow/models/taskinstance.py", line 2676, in _execute_task_with_callbacks
    result = self._execute_task(context, task_orig)
             ^^^^^^^^^^^^^^^^^^^^^^^^^^^^^^^^^^^^^^
  File "/home/airflow/.local/lib/python3.11/site-packages/airflow/models/taskinstance.py", line 2701, in _execute_task
    return _execute_task(self, context, task_orig)
           ^^^^^^^^^^^^^^^^^^^^^^^^^^^^^^^^^^^^^^^
  File "/home/airflow/.local/lib/python3.11/site-packages/airflow/models/taskinstance.py", line 465, in _execute_task
    result = _execute_callable(context=context, **execute_callable_kwargs)
             ^^^^^^^^^^^^^^^^^^^^^^^^^^^^^^^^^^^^^^^^^^^^^^^^^^^^^^^^^^^^^
  File "/home/airflow/.local/lib/python3.11/site-packages/airflow/models/taskinstance.py", line 432, in _execute_callable
    return execute_callable(context=context, **execute_callable_kwargs)
           ^^^^^^^^^^^^^^^^^^^^^^^^^^^^^^^^^^^^^^^^^^^^^^^^^^^^^^^^^^^^
  File "/home/airflow/.local/lib/python3.11/site-packages/airflow/models/baseoperator.py", line 400, in wrapper
    return func(self, *args, **kwargs)
           ^^^^^^^^^^^^^^^^^^^^^^^^^^^
  File "/home/airflow/.local/lib/python3.11/site-packages/airflow/operators/bash.py", line 243, in execute
    raise AirflowException(
airflow.exceptions.AirflowException: Bash command failed. The command returned a non-zero exit code 2.

During handling of the above exception, another exception occurred:

Traceback (most recent call last):
  File "/home/airflow/.local/lib/python3.11/site-packages/airflow/models/taskinstance.py", line 1063, in _email_alert
    send_email(task.email, subject, html_content)
  File "/home/airflow/.local/lib/python3.11/site-packages/airflow/utils/email.py", line 80, in send_email
    return backend(
           ^^^^^^^^
  File "/home/airflow/.local/lib/python3.11/site-packages/airflow/utils/email.py", line 154, in send_email_smtp
    send_mime_email(e_from=mail_from, e_to=recipients, mime_msg=msg, conn_id=conn_id, dryrun=dryrun)
  File "/home/airflow/.local/lib/python3.11/site-packages/airflow/utils/email.py", line 273, in send_mime_email
    smtp_conn = _get_smtp_connection(smtp_host, smtp_port, smtp_timeout, smtp_ssl)
                ^^^^^^^^^^^^^^^^^^^^^^^^^^^^^^^^^^^^^^^^^^^^^^^^^^^^^^^^^^^^^^^^^^
  File "/home/airflow/.local/lib/python3.11/site-packages/airflow/utils/email.py", line 317, in _get_smtp_connection
    return smtplib.SMTP(host=host, port=port, timeout=timeout)
           ^^^^^^^^^^^^^^^^^^^^^^^^^^^^^^^^^^^^^^^^^^^^^^^^^^^
  File "/usr/local/lib/python3.11/smtplib.py", line 255, in __init__
    (code, msg) = self.connect(host, port)
                  ^^^^^^^^^^^^^^^^^^^^^^^^
  File "/usr/local/lib/python3.11/smtplib.py", line 341, in connect
    self.sock = self._get_socket(host, port, self.timeout)
                ^^^^^^^^^^^^^^^^^^^^^^^^^^^^^^^^^^^^^^^^^^
  File "/usr/local/lib/python3.11/smtplib.py", line 312, in _get_socket
    return socket.create_connection((host, port), timeout,
           ^^^^^^^^^^^^^^^^^^^^^^^^^^^^^^^^^^^^^^^^^^^^^^^
  File "/usr/local/lib/python3.11/socket.py", line 851, in create_connection
    raise exceptions[0]
  File "/usr/local/lib/python3.11/socket.py", line 836, in create_connection
    sock.connect(sa)
ConnectionRefusedError: [Errno 111] Connection refused

During handling of the above exception, another exception occurred:

Traceback (most recent call last):
  File "/home/airflow/.local/lib/python3.11/site-packages/airflow/models/taskinstance.py", line 877, in _handle_failure
    task_instance.email_alert(error, failure_context["task"])
  File "/home/airflow/.local/lib/python3.11/site-packages/airflow/models/taskinstance.py", line 3163, in email_alert
    _email_alert(task_instance=self, exception=exception, task=task)
  File "/home/airflow/.local/lib/python3.11/site-packages/airflow/models/taskinstance.py", line 1065, in _email_alert
    send_email(task.email, subject, html_content_err)
  File "/home/airflow/.local/lib/python3.11/site-packages/airflow/utils/email.py", line 80, in send_email
    return backend(
           ^^^^^^^^
  File "/home/airflow/.local/lib/python3.11/site-packages/airflow/utils/email.py", line 154, in send_email_smtp
    send_mime_email(e_from=mail_from, e_to=recipients, mime_msg=msg, conn_id=conn_id, dryrun=dryrun)
  File "/home/airflow/.local/lib/python3.11/site-packages/airflow/utils/email.py", line 273, in send_mime_email
    smtp_conn = _get_smtp_connection(smtp_host, smtp_port, smtp_timeout, smtp_ssl)
                ^^^^^^^^^^^^^^^^^^^^^^^^^^^^^^^^^^^^^^^^^^^^^^^^^^^^^^^^^^^^^^^^^^
  File "/home/airflow/.local/lib/python3.11/site-packages/airflow/utils/email.py", line 317, in _get_smtp_connection
    return smtplib.SMTP(host=host, port=port, timeout=timeout)
           ^^^^^^^^^^^^^^^^^^^^^^^^^^^^^^^^^^^^^^^^^^^^^^^^^^^
  File "/usr/local/lib/python3.11/smtplib.py", line 255, in __init__
    (code, msg) = self.connect(host, port)
                  ^^^^^^^^^^^^^^^^^^^^^^^^
  File "/usr/local/lib/python3.11/smtplib.py", line 341, in connect
    self.sock = self._get_socket(host, port, self.timeout)
                ^^^^^^^^^^^^^^^^^^^^^^^^^^^^^^^^^^^^^^^^^^
  File "/usr/local/lib/python3.11/smtplib.py", line 312, in _get_socket
    return socket.create_connection((host, port), timeout,
           ^^^^^^^^^^^^^^^^^^^^^^^^^^^^^^^^^^^^^^^^^^^^^^^
  File "/usr/local/lib/python3.11/socket.py", line 851, in create_connection
    raise exceptions[0]
  File "/usr/local/lib/python3.11/socket.py", line 836, in create_connection
    sock.connect(sa)
ConnectionRefusedError: [Errno 111] Connection refused
[2025-09-11T10:23:29.567+0000] {standard_task_runner.py:110} ERROR - Failed to execute job 1057 for task dbt_test (Bash command failed. The command returned a non-zero exit code 2.; 2744)
[2025-09-11T10:23:29.624+0000] {local_task_job_runner.py:240} INFO - Task exited with return code 1
[2025-09-11T10:23:29.775+0000] {taskinstance.py:3498} INFO - 0 downstream tasks scheduled from follow-on schedule check
[2025-09-11T10:23:29.860+0000] {local_task_job_runner.py:222} INFO - ::endgroup::
