[2025-09-18T11:09:34.169+0000] {task_context_logger.py:104} ERROR - Executor reports task instance <TaskInstance: 4_logistics_ticket_classifier_full_dag.copy_s3_to_snowflake manual__2025-09-18T11:08:23.319503+00:00 [queued]> finished (failed) although the task says it's queued. (Info: None) Was the task killed externally?
