[2025-09-10T13:39:02.141+0000] {local_task_job_runner.py:120} INFO - ::group::Pre task execution logs
[2025-09-10T13:39:02.387+0000] {taskinstance.py:2076} INFO - Dependencies all met for dep_context=non-requeueable deps ti=<TaskInstance: weather_data_dag.call_weather_rest_api scheduled__2025-07-19T00:00:00+00:00 [queued]>
[2025-09-10T13:39:02.545+0000] {taskinstance.py:2076} INFO - Dependencies all met for dep_context=requeueable deps ti=<TaskInstance: weather_data_dag.call_weather_rest_api scheduled__2025-07-19T00:00:00+00:00 [queued]>
[2025-09-10T13:39:02.546+0000] {taskinstance.py:2306} INFO - Starting attempt 1 of 1
[2025-09-10T13:39:02.719+0000] {taskinstance.py:2330} INFO - Executing <Task(PythonOperator): call_weather_rest_api> on 2025-07-19 00:00:00+00:00
[2025-09-10T13:39:02.747+0000] {standard_task_runner.py:63} INFO - Started process 92 to run task
[2025-09-10T13:39:02.766+0000] {standard_task_runner.py:90} INFO - Running: ['airflow', 'tasks', 'run', 'weather_data_dag', 'call_weather_rest_api', 'scheduled__2025-07-19T00:00:00+00:00', '--job-id', '1040', '--raw', '--subdir', 'DAGS_FOLDER/weather_api_dag.py', '--cfg-path', '/tmp/tmpdibwb8th']
[2025-09-10T13:39:02.789+0000] {standard_task_runner.py:91} INFO - Job 1040: Subtask call_weather_rest_api
[2025-09-10T13:39:05.521+0000] {task_command.py:426} INFO - Running <TaskInstance: weather_data_dag.call_weather_rest_api scheduled__2025-07-19T00:00:00+00:00 [running]> on host aafe33ce491d
[2025-09-10T13:39:13.967+0000] {taskinstance.py:2648} INFO - Exporting env vars: AIRFLOW_CTX_DAG_OWNER='airflow' AIRFLOW_CTX_DAG_ID='weather_data_dag' AIRFLOW_CTX_TASK_ID='call_weather_rest_api' AIRFLOW_CTX_EXECUTION_DATE='2025-07-19T00:00:00+00:00' AIRFLOW_CTX_TRY_NUMBER='1' AIRFLOW_CTX_DAG_RUN_ID='scheduled__2025-07-19T00:00:00+00:00'
[2025-09-10T13:39:13.980+0000] {taskinstance.py:430} INFO - ::endgroup::
[2025-09-10T13:39:14.996+0000] {credentials.py:1278} INFO - Found credentials in shared credentials file: ~/.aws/credentials
[2025-09-10T13:39:24.279+0000] {logging_mixin.py:188} INFO - S3 client initialized.
[2025-09-10T13:39:25.256+0000] {logging_mixin.py:188} INFO - city,timestamp,weather_main,weather_description,temp,feels_like,humidity,wind_speed,clouds
New York,1757511382,Clouds,overcast clouds,16.29,15.93,75,5.74,100
[2025-09-10T13:39:25.887+0000] {taskinstance.py:441} INFO - ::group::Post task execution logs
[2025-09-10T13:39:25.898+0000] {taskinstance.py:2905} ERROR - Task failed with exception
Traceback (most recent call last):
  File "/home/airflow/.local/lib/python3.11/site-packages/airflow/models/taskinstance.py", line 465, in _execute_task
    result = _execute_callable(context=context, **execute_callable_kwargs)
             ^^^^^^^^^^^^^^^^^^^^^^^^^^^^^^^^^^^^^^^^^^^^^^^^^^^^^^^^^^^^^
  File "/home/airflow/.local/lib/python3.11/site-packages/airflow/models/taskinstance.py", line 432, in _execute_callable
    return execute_callable(context=context, **execute_callable_kwargs)
           ^^^^^^^^^^^^^^^^^^^^^^^^^^^^^^^^^^^^^^^^^^^^^^^^^^^^^^^^^^^^
  File "/home/airflow/.local/lib/python3.11/site-packages/airflow/models/baseoperator.py", line 400, in wrapper
    return func(self, *args, **kwargs)
           ^^^^^^^^^^^^^^^^^^^^^^^^^^^
  File "/home/airflow/.local/lib/python3.11/site-packages/airflow/operators/python.py", line 235, in execute
    return_value = self.execute_callable()
                   ^^^^^^^^^^^^^^^^^^^^^^^
  File "/home/airflow/.local/lib/python3.11/site-packages/airflow/operators/python.py", line 252, in execute_callable
    return self.python_callable(*self.op_args, **self.op_kwargs)
           ^^^^^^^^^^^^^^^^^^^^^^^^^^^^^^^^^^^^^^^^^^^^^^^^^^^^^
  File "/opt/airflow/dags/weather_api_dag.py", line 19, in call_weather_api
    fetch_weather_data_save_csv()
  File "/opt/airflow/dags/weather_util.py", line 78, in fetch_weather_data_save_csv
    s3_path = upload_csv_to_s3(s3_client, s3_bucket, s3_folder_name, csv_string)
              ^^^^^^^^^^^^^^^^^^^^^^^^^^^^^^^^^^^^^^^^^^^^^^^^^^^^^^^^^^^^^^^^^^
  File "/opt/airflow/dags/weather_util.py", line 38, in upload_csv_to_s3
    s3_client.put_object(
  File "/home/airflow/.local/lib/python3.11/site-packages/botocore/client.py", line 553, in _api_call
    return self._make_api_call(operation_name, kwargs)
           ^^^^^^^^^^^^^^^^^^^^^^^^^^^^^^^^^^^^^^^^^^^
  File "/home/airflow/.local/lib/python3.11/site-packages/botocore/client.py", line 1009, in _make_api_call
    raise error_class(parsed_response, operation_name)
botocore.exceptions.ClientError: An error occurred (AccessDenied) when calling the PutObject operation: Access Denied
[2025-09-10T13:39:26.434+0000] {taskinstance.py:1206} INFO - Marking task as FAILED. dag_id=weather_data_dag, task_id=call_weather_rest_api, run_id=scheduled__2025-07-19T00:00:00+00:00, execution_date=20250719T000000, start_date=20250910T133902, end_date=20250910T133926
[2025-09-10T13:39:27.867+0000] {standard_task_runner.py:110} ERROR - Failed to execute job 1040 for task call_weather_rest_api (An error occurred (AccessDenied) when calling the PutObject operation: Access Denied; 92)
[2025-09-10T13:39:27.953+0000] {local_task_job_runner.py:240} INFO - Task exited with return code 1
[2025-09-10T13:39:28.451+0000] {logging_mixin.py:188} WARNING - /home/airflow/.local/lib/python3.11/site-packages/airflow/models/baseoperator.py:1296 AirflowProviderDeprecationWarning: Call to deprecated class SnowflakeOperator. (This class is deprecated. Please use `airflow.providers.common.sql.operators.sql.SQLExecuteQueryOperator`. Also, you can provide `hook_params={'warehouse': <warehouse>, 'database': <database>, 'role': <role>, 'schema': <schema>, 'authenticator': <authenticator>,'session_parameters': <session_parameters>}`.)
[2025-09-10T13:39:28.559+0000] {taskinstance.py:3498} INFO - 0 downstream tasks scheduled from follow-on schedule check
[2025-09-10T13:39:29.390+0000] {local_task_job_runner.py:222} INFO - ::endgroup::
